Workbook

Sheet Sheet1
A1: BEB3-12-0400-Daily.Cmol.Consumption | B1: date | C1: time pi datalink | D1: C-mol_Actual | E1: B-mol_Actual | F1: wip C-mol_Actual | G1: wip B-mol_Actual | H1: %FS C-mol_Actual | I1: %FS B-mol_Actual | J1: Ethanol C-mol_Actual | K1: Ethanol B-mol_Actual | L1: Vinasses_Actual | M1: Vinasses Sale_Actual | N1: CF C-mol_Actual | O1: CF B-mol_Actual | P1: CF_Actual | Q1: Yield C-mol_Actual | R1: Yield B-mol_Actual | S1: Yield_Actual | T1: Fuel_Actual | U1: ENA_Actual | V1: DENA_Actual | W1: Name_Production | X1: Ethanol_Actual | Y1: CF C-mol_Plan | Z1: CF B-mol_Plan | AA1: CF_Plan | AB1: Yield C-mol_Plan | AC1: Yield B-mol_Plan | AD1: %FS C-mol_Plan | AE1: %FS B-mol_Plan | AF1: Vinasses_Plan | AG1: Vinasses Sale_Plan | AH1: Fuel_Plan | AI1: ENA_Plan | AJ1: DENA_Plan | AK1: Ethanol_Plan | AL1: Fuel_Report | AM1: ENA_Report | AN1: DENA_Report
A2: BEB3-12-0400-Daily.Bmol.Consumption | B2: 46022 | C2: 46023 | F2: 412380.69 | G2: 159764.11
A3: BEB3-12-0400-Daily.Cmol.WIP | B3: 46023 | C3: 46024 | D3: 243.61018 | E3: 548.63336 | F3: 413369.88 | G3: 162790.62 | H3: 41.949821 | I3: 57.010777 | J3: 62391.559 | K3: 190958.56 | L3: 1273.7815 | M3: 0.45993054 | N3: 0.62020004 | O3: 0.62019628 | P3: 0.6201972 | Q3: 260.17162 | R3: 353.57924 | S3: 324.85695 | T3: 254226.98 | U3: 0 | V3: 0 | W3: Fuel | X3: 253350.12 | Y3: 0.617 | Z3: 0.624 | AA3: 0.62 | AB3: 264.32 | AC3: 323.34 | AD3: 44.27 | AE3: 52.51 | AF3: 1400 | AG3: 1667 | AH3: 253500 | AI3: 0 | AJ3: 0 | AK3: 250000 | AL3: 254226.98 | AM3: -238.99701 | AN3: -636.99475
A4: BEB3-12-0400-Daily.Bmol.WIP | B4: 46024 | C4: 46025 | D4: 243.88043 | E4: 539.03607 | F4: 413196.31 | G4: 162258.03 | H4: 41.690151 | I4: 58.130222 | J4: 61757.609 | K4: 190326.17 | L4: 1246.9928 | M4: 662.94604 | N4: 0.60570031 | O4: 0.60570576 | P4: 0.60570442 | Q4: 252.51909 | R4: 352.09733 | S4: 321.07846 | T4: 252246.02 | U4: 0 | V4: 0 | W4: Fuel | X4: 252083.78 | Y4: 0.617 | Z4: 0.624 | AA4: 0.62 | AB4: 264.32 | AC4: 323.34 | AD4: 44.27 | AE4: 52.51 | AF4: 1400 | AG4: 1667 | AH4: 253500 | AI4: 0 | AJ4: 0 | AK4: 250000 | AL4: 252246.02 | AM4: 18.992176 | AN4: -182 | AR4: =B33 -> 46053
A5: BEB3-52-0400-Daily.Cmol.FS | B5: 46025 | C5: 46026 | D5: 244.48972 | E5: 533.43311 | F5: 416520.31 | G5: 172371.94 | H5: 41.909832 | I5: 58.449966 | J5: 62632.969 | K5: 190583.89 | L5: 1236.6178 | M5: 1592.5013 | N5: 0.64370098 | O5: 0.64369239 | P5: 0.64369451 | Q5: 269.77129 | R5: 376.23923 | S5: 342.77792 | T5: 254054.03 | U5: 0 | V5: 0 | W5: Fuel | X5: 253216.86 | Y5: 0.617 | Z5: 0.624 | AA5: 0.62 | AB5: 264.32 | AC5: 323.34 | AD5: 44.27 | AE5: 52.51 | AF5: 1400 | AG5: 1667 | AH5: 253500 | AI5: 0 | AJ5: 0 | AK5: 250000 | AL5: 254054.03 | AM5: -656.99597 | AN5: -182.00113
A6: BEB3-52-0400-Daily.Bmol.FS | B6: 46026 | C6: 46027 | D6: 244.0706 | E6: 537.8927 | F6: 416956.47 | G6: 173719.34 | H6: 41.670101 | I6: 58.399952 | J6: 62587.641 | K6: 193310.09 | L6: 1262.1816 | M6: 1407.0696 | N6: 0.6196758 | O6: 0.61967361 | P6: 0.61967415 | Q6: 258.21884 | R6: 361.8894 | S6: 329.53119 | T6: 256489.97 | U6: 0 | V6: 0 | W6: Fuel | X6: 255897.73 | Y6: 0.617 | Z6: 0.624 | AA6: 0.62 | AB6: 264.32 | AC6: 323.34 | AD6: 44.27 | AE6: 52.51 | AF6: 1400 | AG6: 1667 | AH6: 253500 | AI6: 0 | AJ6: 0 | AK6: 250000 | AL6: 256489.97 | AM6: -310.99872 | AN6: -279.99744
A7: BEB3-12-0800-Daily.Cmol.Ethanol | B7: 46027 | C7: 46028 | D7: 230.55075 | E7: 527.37274 | F7: 416210.62 | G7: 171336.84 | H7: 41.820026 | I7: 58.329731 | J7: 60632.477 | K7: 193446.22 | L7: 1235.9225 | M7: 1075.1974 | N7: 0.62112506 | O7: 0.62111294 | P7: 0.62111583 | Q7: 259.7508 | R7: 362.29519 | S7: 331.10248 | T7: 254336.03 | U7: 0 | V7: 0 | W7: Fuel | X7: 254078.7 | Y7: 0.617 | Z7: 0.624 | AA7: 0.62 | AB7: 264.32 | AC7: 323.34 | AD7: 44.27 | AE7: 52.51 | AF7: 1400 | AG7: 1667 | AH7: 253500 | AI7: 0 | AJ7: 0 | AK7: 250000 | AL7: 254336.03 | AM7: -200.99968 | AN7: -58.001713
A8: BEB3-12-0800-Daily.Bmol.Ethanol | B8: 46028 | C8: 46029 | D8: 246.03555 | E8: 516.96991 | F8: 417119.81 | G8: 173981.48 | H8: 41.861141 | I8: 57.93959 | J8: 65632.414 | K8: 190874.48 | L8: 1268.2812 | M8: 869.73999 | N8: 0.64607705 | O8: 0.6460754 | P8: 0.64607582 | Q8: 270.45471 | R8: 374.33369 | S8: 340.83731 | T8: 256887.97 | U8: 0 | V8: 0 | W8: Fuel | X8: 256506.9 | Y8: 0.617 | Z8: 0.624 | AA8: 0.62 | AB8: 264.32 | AC8: 323.34 | AD8: 44.27 | AE8: 52.51 | AF8: 1400 | AG8: 1667 | AH8: 253500 | AI8: 0 | AJ8: 0 | AK8: =SUM(AH8:AJ8) -> 253500 | AL8: 256887.97 | AM8: -173.00816 | AN8: -205.99663
A9: BEB3-72-0700-Daily.Vinasses.Volume | B9: 46029 | C9: 46030 | D9: 239.63658 | E9: 545.58508 | F9: 416872.28 | G9: 173240.92 | H9: 43.500679 | I9: 57.348324 | J9: 63348.84 | K9: 190140 | L9: 1241.2524 | M9: 538.88287 | N9: 0.60532584 | O9: 0.60533456 | P9: 0.60533238 | Q9: 263.3237 | R9: 347.14797 | S9: 321.5662 | T9: 254282.98 | U9: 0 | V9: 0 | W9: Fuel | X9: 253488.84 | Y9: 0.617 | Z9: 0.624 | AA9: 0.62 | AB9: 264.32 | AC9: 323.34 | AD9: 44.27 | AE9: 52.51 | AF9: 1400 | AG9: 1667 | AH9: 253500 | AI9: 0 | AJ9: 0 | AK9: =SUM(AH9:AJ9) -> 253500 | AL9: 254282.98 | AM9: -878.00317 | AN9: 84.992538
A10: BEB3-72-0700-Daily.Vinasses.Distributed | B10: 46030 | C10: 46031 | D10: 220.33017 | E10: 567.28314 | F10: 417290 | G10: 174566.86 | H10: 44.479805 | I10: 54.939575 | J10: 60240.02 | K10: 191572.31 | L10: 1172.5621 | M10: 629.2785 | N10: 0.61894117 | O10: 0.61893225 | P10: 0.61893438 | Q10: 275.30081 | R10: 340.03992 | S10: 321.92954 | T10: 253522 | U10: 0 | V10: 0 | W10: Fuel | X10: 251812.33 | Y10: 0.617 | Z10: 0.624 | AA10: 0.62 | AB10: 264.32 | AC10: 323.34 | AD10: 44.27 | AE10: 52.51 | AF10: 1400 | AG10: 1667 | AH10: 253500 | AI10: 0 | AJ10: 0 | AK10: =SUM(AH10:AJ10) -> 253500 | AL10: 253522 | AM10: -1150.0021 | AN10: -559.99628
A11: BEB3-12-0800-Daily.Ethanol.Fuel | B11: 46031 | C11: 46032 | D11: 220.57399 | E11: 571.78479 | F11: 415868.25 | G11: 170035.48 | H11: 44.200146 | I11: 54.329906 | J11: 60264.141 | K11: 192021.89 | L11: 974.44586 | M11: 569.6106 | N11: 0.60354869 | O11: 0.60354235 | P11: 0.60354386 | Q11: 266.76727 | R11: 327.90482 | S11: 310.88556 | T11: 253856.97 | U11: 0 | V11: 0 | W11: Fuel | X11: 252286.03 | Y11: 0.617 | Z11: 0.624 | AA11: 0.62 | AB11: 264.32 | AC11: 323.34 | AD11: 44.27 | AE11: 52.51 | AF11: 1400 | AG11: 1667 | AH11: 253500 | AI11: 0 | AJ11: 0 | AK11: =SUM(AH11:AJ11) -> 253500 | AL11: 253856.97 | AM11: -1332.9971 | AN11: -235.99979
A12: BEB3-12-0800-Daily.Ethanol.ENA | B12: 46032 | C12: 46033 | D12: 211.93591 | E12: 578.6767 | F12: 414780.69 | G12: 166415.92 | H12: 44.409904 | I12: 54.190372 | J12: 57590.078 | K12: 191876.23 | L12: 1328.2227 | M12: 613.49969 | N12: 0.6003208 | O12: 0.60033304 | P12: 0.60033021 | Q12: 266.60608 | R12: 325.32118 | S12: 309.58169 | T12: 250760.05 | U12: 0 | V12: 0 | W12: Fuel | X12: 249466.31 | Y12: 0.617 | Z12: 0.624 | AA12: 0.62 | AB12: 264.32 | AC12: 323.34 | AD12: 44.27 | AE12: 52.51 | AF12: 1400 | AG12: 1667 | AH12: 253500 | AI12: 0 | AJ12: 0 | AK12: =SUM(AH12:AJ12) -> 253500 | AL12: 250760.05 | AM12: -1078.9977 | AN12: -217.99872
A13: BEB3-12-0800-Daily.Ethanol.D-ENA | B13: 46033 | C13: 46034 | D13: 220.46027 | E13: 588.29633 | F13: 414310.5 | G13: 164864.39 | H13: 44.27034 | I13: 54.730049 | J13: 59140.801 | K13: 195101.84 | L13: 1360.9586 | M13: 411.586 | N13: 0.60114251 | O13: 0.60113485 | P13: 0.60113663 | Q13: 266.12523 | R13: 329.00237 | S13: 311.86259 | T13: 255225 | U13: 0 | V13: 0 | W13: Fuel | X13: 254242.64 | Y13: 0.617 | Z13: 0.624 | AA13: 0.62 | AB13: 264.32 | AC13: 323.34 | AD13: 44.27 | AE13: 52.51 | AF13: 1400 | AG13: 1667 | AH13: 253500 | AI13: 0 | AJ13: 0 | AK13: =SUM(AH13:AJ13) -> 253500 | AL13: 255225 | AM13: -875.99408 | AN13: -107.00066
B14: 46034 | C14: 46035 | D14: 220.8304 | E14: 582.98779 | F14: 413591.66 | G14: 162540.92 | H14: 44.760048 | I14: 54.800026 | J14: 60293.828 | K14: 194877.08 | L14: 1445.236 | M14: 391.47308 | N14: 0.60271852 | O14: 0.60271422 | P14: 0.60271524 | Q14: 269.77563 | R14: 330.28811 | S14: 313.66371 | T14: 255702.98 | U14: 0 | V14: 0 | W14: Fuel | X14: 255170.91 | Y14: 0.617 | Z14: 0.624 | AA14: 0.62 | AB14: 264.32 | AC14: 323.34 | AD14: 44.27 | AE14: 52.51 | AF14: 1400 | AG14: 1667 | AH14: 253500 | AI14: 0 | AJ14: 0 | AK14: =SUM(AH14:AJ14) -> 253500 | AL14: 255702.98 | AM14: -366.9949 | AN14: -163.99997
B15: 46035 | C15: 46036 | D15: 221.40944 | E15: 565.4325 | F15: 413092.34 | G15: 160980.05 | H15: 44.82975 | I15: 54.840187 | J15: 61486.797 | K15: 192114 | L15: 1496.9966 | M15: 439.02762 | N15: 0.61443829 | O15: 0.61452051 | P15: 0.61450057 | Q15: 275.47907 | R15: 336.99326 | S15: 319.68379 | T15: 253689.98 | U15: 0 | V15: 0 | W15: Fuel | X15: 253600.8 | Y15: 0.617 | Z15: 0.624 | AA15: 0.62 | AB15: 264.32 | AC15: 323.34 | AD15: 44.27 | AE15: 52.51 | AF15: 1400 | AG15: 1667 | AH15: 253500 | AI15: 0 | AJ15: 0 | AK15: =SUM(AH15:AJ15) -> 253500 | AL15: 253689.98 | AM15: 73.002769 | AN15: -161.0125
B16: 46036 | C16: 46037 | D16: 220.6002 | E16: 554.67169 | F16: 413576.28 | G16: 162485.92 | H16: 44.470425 | I16: 55.109875 | J16: 61194.559 | K16: 190679.55 | L16: 1492.1351 | M16: 363.65778 | N16: 0.62871901 | O16: 0.62871673 | P16: 0.62871728 | Q16: 279.59324 | R16: 346.48531 | S16: 327.45146 | T16: 252801 | U16: 0 | V16: 0 | W16: Fuel | X16: 251874.11 | Y16: 0.617 | Z16: 0.624 | AA16: 0.62 | AB16: 264.32 | AC16: 323.34 | AD16: 44.27 | AE16: 52.51 | AF16: 1400 | AG16: 1667 | AH16: 253500 | AI16: 0 | AJ16: 0 | AK16: =SUM(AH16:AJ16) -> 253500 | AL16: 252801 | AM16: 312.00061 | AN16: -1240.968
B17: 46037 | C17: 46038 | D17: 220.8802 | E17: 600.24164 | F17: 413979.28 | G17: 163823.84 | H17: 45.079994 | I17: 54.929897 | J17: 59116.246 | K17: 195777.8 | L17: 1542.6735 | M17: 317.32333 | N17: 0.59774614 | O17: 0.5978419 | P17: 0.59781969 | Q17: 269.49708 | R17: 328.38174 | S17: 312.54188 | T17: 253021.72 | U17: 0 | V17: 0 | W17: Fuel | X17: 254894.04 | Y17: 0.617 | Z17: 0.624 | AA17: 0.62 | AB17: 264.32 | AC17: 323.34 | AD17: 44.27 | AE17: 52.51 | AF17: 1400 | AG17: 1667 | AH17: 253500 | AI17: 0 | AJ17: 0 | AK17: =SUM(AH17:AJ17) -> 253500 | AL17: 253021.72 | AM17: 365.00171 | AN17: 1524.9822
B18: 46038 | C18: 46039 | D18: 221.1629 | E18: 573.7887 | F18: 414364.16 | G18: 165035.16 | H18: 45.069466 | I18: 54.779785 | J18: 55152.234 | K18: 173916.69 | L18: 1360.6451 | M18: 394.0658 | N18: 0.5571711 | O18: 0.55716429 | P18: 0.55716593 | Q18: 251.11171 | R18: 305.2143 | S18: 290.16246 | T18: 228562.12 | U18: 0 | V18: 0 | W18: Fuel | X18: 229068.92 | Y18: 0.617 | Z18: 0.624 | AA18: 0.62 | AB18: 264.32 | AC18: 323.34 | AD18: 44.27 | AE18: 52.51 | AF18: 1400 | AG18: 1667 | AH18: 253500 | AI18: 0 | AJ18: 0 | AK18: =SUM(AH18:AJ18) -> 253500 | AL18: 228562.12 | AM18: 511.99725 | AN18: -12.997778
B19: 46039 | C19: 46040 | D19: 210.95721 | E19: 571.92914 | F19: 417456.38 | G19: 175346.19 | H19: 44.300716 | I19: 54.469612 | J19: 55496.496 | K19: 184991.47 | L19: 1425.61 | M19: 344.75568 | N19: 0.62691526 | O19: 0.6269188 | P19: 0.62691799 | Q19: 277.72916 | R19: 341.4798 | S19: 324.3015 | T19: 240025.12 | U19: 0 | V19: 0 | W19: Fuel | X19: 240487.96 | Y19: 0.617 | Z19: 0.624 | AA19: 0.62 | AB19: 264.32 | AC19: 323.34 | AD19: 44.27 | AE19: 52.51 | AF19: 1400 | AG19: 1667 | AH19: 253500 | AI19: 0 | AJ19: 0 | AK19: =SUM(AH19:AJ19) -> 253500 | AL19: 240025.12 | AM19: 276.00336 | AN19: 178.99873
B20: 46040 | C20: 46041 | D20: 221.34343 | E20: 570.67792 | F20: 419421.03 | G20: 181368.08 | H20: 45.330254 | I20: 53.909576 | J20: 61963.441 | K20: 189993.27 | L20: 1440.04 | M20: 252.3266 | N20: 0.63714312 | O20: 0.63713676 | P20: 0.63713833 | Q20: 288.81642 | R20: 343.47857 | S20: 328.20233 | T20: 251318.06 | U20: 0 | V20: 0 | W20: Fuel | X20: 251956.71 | Y20: 0.617 | Z20: 0.624 | AA20: 0.62 | AB20: 264.32 | AC20: 323.34 | AD20: 44.27 | AE20: 52.51 | AF20: 1400 | AG20: 1667 | AH20: 253500 | AI20: 0 | AJ20: 0 | AK20: =SUM(AH20:AJ20) -> 253500 | AL20: 251318.06 | AM20: 566.00024 | AN20: 69.984886
B21: 46041 | C21: 46042 | D21: 211.8869 | E21: 596.49707 | F21: 419454.16 | G21: 181475.53 | H21: 45.690269 | I21: 53.30093 | J21: 59722.125 | K21: 196131.67 | L21: 1497.8231 | M21: 477.59836 | N21: 0.61723172 | O21: 0.61722356 | P21: 0.61722547 | Q21: 282.01198 | R21: 328.98691 | S21: 316.67423 | T21: 256503.98 | U21: 0 | V21: 0 | W21: Fuel | X21: 255853.8 | Y21: 0.617 | Z21: 0.624 | AA21: 0.62 | AB21: 264.32 | AC21: 323.34 | AD21: 44.27 | AE21: 52.51 | AF21: 1400 | AG21: 1667 | AH21: 253500 | AI21: 0 | AJ21: 0 | AK21: =SUM(AH21:AJ21) -> 253500 | AL21: 256503.98 | AM21: 585.99109 | AN21: -1235.9852
B22: 46042 | C22: 46043 | D22: 221.8179 | E22: 592.32001 | F22: 419694 | G22: 182237.03 | H22: 46.079967 | I22: 54.6395 | J22: 61340.68 | K22: 194224.19 | L22: 1818.9307 | M22: 374.48972 | N22: 0.60246888 | O22: 0.60247581 | P22: 0.60247415 | Q22: 277.61989 | R22: 329.18886 | S22: 315.13851 | T22: 255702.98 | U22: 0 | V22: 0 | W22: Fuel | X22: 255564.87 | Y22: 0.617 | Z22: 0.624 | AA22: 0.62 | AB22: 264.32 | AC22: 323.34 | AD22: 44.27 | AE22: 52.51 | AF22: 1400 | AG22: 1667 | AH22: 253500 | AI22: 0 | AJ22: 0 | AK22: =SUM(AH22:AJ22) -> 253500 | AL22: 255702.98 | AM22: -181.99809 | AN22: 45.000046
B23: 46043 | C23: 46044 | D23: 218.7789 | E23: 592.30786 | F23: 419705.91 | G23: 182275.14 | H23: 46.02977 | I23: 53.919861 | J23: 60874.719 | K23: 193058.36 | L23: 1862.9642 | M23: 402.97894 | N23: 0.60461325 | O23: 0.60461382 | P23: 0.60461369 | Q23: 278.30229 | R23: 326.00686 | S23: 313.13924 | T23: 253901.98 | U23: 0 | V23: 0 | W23: Fuel | X23: 253933.08 | Y23: 0.617 | Z23: 0.624 | AA23: 0.62 | AB23: 264.32 | AC23: 323.34 | AD23: 44.27 | AE23: 52.51 | AF23: 1400 | AG23: 1667 | AH23: 253500 | AI23: 0 | AJ23: 0 | AK23: =SUM(AH23:AJ23) -> 253500 | AL23: 253901.98 | AM23: -17.00066 | AN23: 48.999283
B24: 46044 | C24: 46045 | D24: 202.82693 | E24: 603.6225 | F24: 420998.31 | G24: 186793.42 | H24: 45.700188 | I24: 53.719933 | J24: 56155.934 | K24: 196451.8 | L24: 1667.2367 | M24: 588.73041 | N24: 0.61977474 | O24: 0.61976996 | P24: 0.61977103 | Q24: 283.23652 | R24: 332.94058 | S24: 320.4397 | T24: 252693.03 | U24: 0 | V24: 0 | W24: Fuel | X24: 252607.73 | Y24: 0.617 | Z24: 0.624 | AA24: 0.62 | AB24: 264.32 | AC24: 323.34 | AD24: 44.27 | AE24: 52.51 | AF24: 1400 | AG24: 1667 | AH24: 253500 | AI24: 0 | AJ24: 0 | AK24: =SUM(AH24:AJ24) -> 253500 | AL24: 252693.03 | AM24: -73.995117 | AN24: -13.001041
B25: 46045 | C25: 46046 | D25: 212.79378 | E25: 607.19617 | F25: 422904.78 | G25: 193141.66 | H25: 45.970181 | I25: 53.620327 | J25: 58934.16 | K25: 196152.47 | L25: 1144.5388 | M25: 862.70111 | N25: 0.62195442 | O25: 0.62196802 | P25: 0.62196488 | Q25: 285.91838 | R25: 333.4996 | S25: 321.1519 | T25: 254845.94 | U25: 0 | V25: 0 | W25: Fuel | X25: 255086.63 | Y25: 0.617 | Z25: 0.624 | AA25: 0.62 | AB25: 264.32 | AC25: 323.34 | AD25: 44.27 | AE25: 52.51 | AF25: 1400 | AG25: 1667 | AH25: 253500 | AI25: 0 | AJ25: 0 | AK25: =SUM(AH25:AJ25) -> 253500 | AL25: 254845.94 | AM25: 347.9928 | AN25: -102.99984
... B55: 46075 | C55: 46076 | D55: 212.88 | E55: 614.21002 | F55: 403477 | G55: 138621 | H55: 45.709999 | I55: 52.110001 | J55: 59284 | K55: 194998 | L55: 1603 | M55: 1991.48 | N55: 0.62011954 | O55: 0.62012614 | P55: 0.6201246 | Q55: 283.45895 | R55: 323.14693 | S55: 312.93187 | T55: 257823 | U55: 0 | V55: 0 | W55: Fuel | X55: 254282 | Y55: 0.617 | Z55: 0.624 | AA55: 0.62 | AB55: 264.32 | AC55: 323.34 | AD55: 44.27 | AE55: 52.51 | AF55: 1072 | AG55: 830 | AH55: 252143 | AI55: 0 | AJ55: 0 | AK55: =SUM(AH55:AJ55) -> 252143 | AL55: 257823 | AM55: -237 | AN55: 125
B56: 46076 | C56: 46077 | D56: =_xll.PIArcVal(Sheet1!$A$1,Sheet1!C56,0,"","auto") -> 203.48 | E56: =_xll.PIArcVal(Sheet1!$A$2,Sheet1!C56,0,"","auto") -> 621.25 | F56: =_xll.PIArcVal(Sheet1!$A$3,Sheet1!C56,0,"","auto") -> 403956 | G56: =_xll.PIArcVal(Sheet1!$A$4,Sheet1!C56,0,"","auto") -> 140305 | H56: =_xll.PIArcVal(Sheet1!$A$5,Sheet1!C56,0,"","auto") -> 45.23 | I56: =_xll.PIArcVal(Sheet1!$A$6,Sheet1!C56,0,"","auto") -> 52.130001 | J56: =_xll.PIArcVal(Sheet1!$A$7,Sheet1!C56,0,"","auto") -> 57052 | K56: =_xll.PIArcVal(Sheet1!$A$8,Sheet1!C56,0,"","auto") -> 200759 | L56: =_xll.PIArcVal(Sheet1!$A$9,Sheet1!C56,0,"","auto") -> 1432.4 | M56: =_xll.PIArcVal(Sheet1!$A$10,Sheet1!C56,0,"","auto") -> 1232.3199 | N56: =(J56+F56-F55)/(D56*H56/100)/1000 -> 0.62510593 | O56: =(K56+G56-G55)/(E56*I56/100)/1000 -> 0.62509875 | P56: =((J56+K56)+F56+G56-F55-G55)/(D56*H56/100+E56*I56/100)/1000 -> 0.62510034 | Q56: =P56*H56*10 -> 282.73288 | R56: =P56*I56*10 -> 325.86481 | S56: =((J56+K56)+F56+G56-F55-G55)/(D56+E56) -> 315.22317 | T56: =IF(AL56<3000,0,AL56) -> 257769 | U56: =IF(AM56<3000,0,AM56) -> 0 | V56: =IF(AN56<3000,0,AN56) -> 0 | W56: Fuel | X56: =J56+K56 -> 257811 | Y56: 0.617 | Z56: 0.624 | AA56: 0.62 | AB56: 264.32 | AC56: 323.34 | AD56: 44.27 | AE56: 52.51 | AF56: 1072 | AG56: 830 | AH56: 252143 | AI56: 0 | AJ56: 0 | AK56: =SUM(AH56:AJ56) -> 252143 | AL56: =_xll.PIArcVal(Sheet1!$A$11,Sheet1!C56,0,"","auto") -> 257769 | AM56: =_xll.PIArcVal(Sheet1!$A$12,Sheet1!C56,0,"","auto") -> 65 | AN56: =_xll.PIArcVal(Sheet1!$A$13,Sheet1!C56,0,"","auto") -> -23
B57: 46077 | C57: 46078 | D57: =_xll.PIArcVal(Sheet1!$A$1,Sheet1!C57,0,"","auto") -> 212.36 | E57: =_xll.PIArcVal(Sheet1!$A$2,Sheet1!C57,0,"","auto") -> 622.54999 | F57: =_xll.PIArcVal(Sheet1!$A$3,Sheet1!C57,0,"","auto") -> 406996 | G57: =_xll.PIArcVal(Sheet1!$A$4,Sheet1!C57,0,"","auto") -> 150504 | H57: =_xll.PIArcVal(Sheet1!$A$5,Sheet1!C57,0,"","auto") -> 45.259998 | I57: =_xll.PIArcVal(Sheet1!$A$6,Sheet1!C57,0,"","auto") -> 51.790001 | J57: =_xll.PIArcVal(Sheet1!$A$7,Sheet1!C57,0,"","auto") -> 59800 | K57: =_xll.PIArcVal(Sheet1!$A$8,Sheet1!C57,0,"","auto") -> 200600 | L57: =_xll.PIArcVal(Sheet1!$A$9,Sheet1!C57,0,"","auto") -> 1475.5 | M57: =_xll.PIArcVal(Sheet1!$A$10,Sheet1!C57,0,"","auto") -> 2343.78 | N57: =(J57+F57-F56)/(D57*H57/100)/1000 -> 0.65380603 | O57: =(K57+G57-G56)/(E57*I57/100)/1000 -> 0.65380524 | P57: =((J57+K57)+F57+G57-F56-G56)/(D57*H57/100+E57*I57/100)/1000 -> 0.65380542 | Q57: =P57*H57*10 -> 295.91232 | R57: =P57*I57*10 -> 338.60584 | S57: =((J57+K57)+F57+G57-F56-G56)/(D57+E57) -> 327.74671 | T57: =IF(AL57<3000,0,AL57) -> 257769 | U57: =IF(AM57<3000,0,AM57) -> 0 | V57: =IF(AN57<3000,0,AN57) -> 0 | W57: Fuel | X57: =J57+K57 -> 260400 | Y57: 0.617 | Z57: 0.624 | AA57: 0.62 | AB57: 264.32 | AC57: 323.34 | AD57: 44.27 | AE57: 52.51 | AF57: 1072 | AG57: 830 | AH57: 252143 | AI57: 0 | AJ57: 0 | AK57: =SUM(AH57:AJ57) -> 252143 | AL57: =_xll.PIArcVal(Sheet1!$A$11,Sheet1!C57,0,"","auto") -> 257769 | AM57: =_xll.PIArcVal(Sheet1!$A$12,Sheet1!C57,0,"","auto") -> 65 | AN57: =_xll.PIArcVal(Sheet1!$A$13,Sheet1!C57,0,"","auto") -> -23
B58: 46078 | C58: 46079 | D58: =_xll.PIArcVal(Sheet1!$A$1,Sheet1!C58,0,"","auto") -> 212.78 | E58: =_xll.PIArcVal(Sheet1!$A$2,Sheet1!C58,0,"","auto") -> 584.28998 | F58: =_xll.PIArcVal(Sheet1!$A$3,Sheet1!C58,0,"","auto") -> 404172 | G58: =_xll.PIArcVal(Sheet1!$A$4,Sheet1!C58,0,"","auto") -> 141657 | H58: =_xll.PIArcVal(Sheet1!$A$5,Sheet1!C58,0,"","auto") -> 45.080002 | I58: =_xll.PIArcVal(Sheet1!$A$6,Sheet1!C58,0,"","auto") -> 51.419998 | J58: =_xll.PIArcVal(Sheet1!$A$7,Sheet1!C58,0,"","auto") -> 64037 | K58: =_xll.PIArcVal(Sheet1!$A$8,Sheet1!C58,0,"","auto") -> 200575 | L58: =_xll.PIArcVal(Sheet1!$A$9,Sheet1!C58,0,"","auto") -> 1418.3 | M58: =_xll.PIArcVal(Sheet1!$A$10,Sheet1!C58,0,"","auto") -> 2072.98 | N58: =(J58+F58-F57)/(D58*H58/100)/1000 -> 0.63815906 | O58: =(K58+G58-G57)/(E58*I58/100)/1000 -> 0.63815334 | P58: =((J58+K58)+F58+G58-F57-G57)/(D58*H58/100+E58*I58/100)/1000 -> 0.63815473 | Q58: =P58*H58*10 -> 287.68016 | R58: =P58*I58*10 -> 328.13915 | S58: =((J58+K58)+F58+G58-F57-G57)/(D58+E58) -> 317.33851 | T58: =IF(AL58<3000,0,AL58) -> 260673 | U58: =IF(AM58<3000,0,AM58) -> 0 | V58: =IF(AN58<3000,0,AN58) -> 0 | W58: Fuel | X58: =J58+K58 -> 264612 | Y58: 0.617 | Z58: 0.624 | AA58: 0.62 | AB58: 264.32 | AC58: 323.34 | AD58: 44.27 | AE58: 52.51 | AF58: 1072 | AG58: 830 | AH58: 252143 | AI58: 0 | AJ58: 0 | AK58: =SUM(AH58:AJ58) -> 252143 | AL58: =_xll.PIArcVal(Sheet1!$A$11,Sheet1!C58,0,"","auto") -> 260673 | AM58: =_xll.PIArcVal(Sheet1!$A$12,Sheet1!C58,0,"","auto") -> -219 | AN58: =_xll.PIArcVal(Sheet1!$A$13,Sheet1!C58,0,"","auto") -> -54
B59: 46079 | C59: 46080 | D59: =_xll.PIArcVal(Sheet1!$A$1,Sheet1!C59,0,"","auto") -> 203.05 | E59: =_xll.PIArcVal(Sheet1!$A$2,Sheet1!C59,0,"","auto") -> 592.60999 | F59: =_xll.PIArcVal(Sheet1!$A$3,Sheet1!C59,0,"","auto") -> 404537 | G59: =_xll.PIArcVal(Sheet1!$A$4,Sheet1!C59,0,"","auto") -> 142870 | H59: =_xll.PIArcVal(Sheet1!$A$5,Sheet1!C59,0,"","auto") -> 45.029999 | I59: =_xll.PIArcVal(Sheet1!$A$6,Sheet1!C59,0,"","auto") -> 51.27 | J59: =_xll.PIArcVal(Sheet1!$A$7,Sheet1!C59,0,"","auto") -> 58715 | K59: =_xll.PIArcVal(Sheet1!$A$8,Sheet1!C59,0,"","auto") -> 195109 | L59: =_xll.PIArcVal(Sheet1!$A$9,Sheet1!C59,0,"","auto") -> 1481.9 | M59: =_xll.PIArcVal(Sheet1!$A$10,Sheet1!C59,0,"","auto") -> 1844.96 | N59: =(J59+F59-F58)/(D59*H59/100)/1000 -> 0.64615328 | O59: =(K59+G59-G58)/(E59*I59/100)/1000 -> 0.64615496 | P59: =((J59+K59)+F59+G59-F58-G58)/(D59*H59/100+E59*I59/100)/1000 -> 0.64615457 | Q59: =P59*H59*10 -> 290.9634 | R59: =P59*I59*10 -> 331.28345 | S59: =((J59+K59)+F59+G59-F58-G58)/(D59+E59) -> 320.9939 | T59: =IF(AL59<3000,0,AL59) -> 261073 | U59: =IF(AM59<3000,0,AM59) -> 0 | V59: =IF(AN59<3000,0,AN59) -> 4150 | W59: Fuel | X59: =J59+K59 -> 253824 | Y59: 0.617 | Z59: 0.624 | AA59: 0.62 | AB59: 264.32 | AC59: 323.34 | AD59: 44.27 | AE59: 52.51 | AF59: 1072 | AG59: 830 | AH59: 252143 | AI59: 0 | AJ59: 0 | AK59: =SUM(AH59:AJ59) -> 252143 | AL59: =_xll.PIArcVal(Sheet1!$A$11,Sheet1!C59,0,"","auto") -> 261073 | AM59: =_xll.PIArcVal(Sheet1!$A$12,Sheet1!C59,0,"","auto") -> -611 | AN59: =_xll.PIArcVal(Sheet1!$A$13,Sheet1!C59,0,"","auto") -> 4150
B60: 46080 | C60: 46081 | D60: =_xll.PIArcVal(Sheet1!$A$1,Sheet1!C60,0,"","auto") -> 212.24352 | E60: =_xll.PIArcVal(Sheet1!$A$2,Sheet1!C60,0,"","auto") -> 556.39813 | F60: =_xll.PIArcVal(Sheet1!$A$3,Sheet1!C60,0,"","auto") -> 402737.38 | G60: =_xll.PIArcVal(Sheet1!$A$4,Sheet1!C60,0,"","auto") -> 137431.11 | H60: =_xll.PIArcVal(Sheet1!$A$5,Sheet1!C60,0,"","auto") -> 45.089577 | I60: =_xll.PIArcVal(Sheet1!$A$6,Sheet1!C60,0,"","auto") -> 52.010174 | J60: =_xll.PIArcVal(Sheet1!$A$7,Sheet1!C60,0,"","auto") -> 63181.398 | K60: =_xll.PIArcVal(Sheet1!$A$8,Sheet1!C60,0,"","auto") -> 191051.3 | L60: =_xll.PIArcVal(Sheet1!$A$9,Sheet1!C60,0,"","auto") -> 1445.3 | M60: =_xll.PIArcVal(Sheet1!$A$10,Sheet1!C60,0,"","auto") -> 1619.16 | N60: =(J60+F60-F59)/(D60*H60/100)/1000 -> 0.64139984 | O60: =(K60+G60-G59)/(E60*I60/100)/1000 -> 0.64140602 | P60: =((J60+K60)+F60+G60-F59-G59)/(D60*H60/100+E60*I60/100)/1000 -> 0.64140448 | Q60: =P60*H60*10 -> 289.20657 | R60: =P60*I60*10 -> 333.59559 | S60: =((J60+K60)+F60+G60-F59-G59)/(D60+E60) -> 321.33853 | T60: =IF(AL60<3000,0,AL60) -> 255213.8 | U60: =IF(AM60<3000,0,AM60) -> 0 | V60: =IF(AN60<3000,0,AN60) -> 0 | W60: Fuel | X60: =J60+K60 -> 254232.7 | Y60: 0.617 | Z60: 0.624 | AA60: 0.62 | AB60: 264.32 | AC60: 323.34 | AD60: 44.27 | AE60: 52.51 | AF60: 1072 | AG60: 830 | AH60: 252143 | AI60: 0 | AJ60: 0 | AK60: =SUM(AH60:AJ60) -> 252143 | AL60: =_xll.PIArcVal(Sheet1!$A$11,Sheet1!C60,0,"","auto") -> 255213.8 | AM60: =_xll.PIArcVal(Sheet1!$A$12,Sheet1!C60,0,"","auto") -> -936.77106 | AN60: =_xll.PIArcVal(Sheet1!$A$13,Sheet1!C60,0,"","auto") -> 12.999433
B61: 46081 | C61: 46082 | D61: =_xll.PIArcVal(Sheet1!$A$1,Sheet1!C61,0,"","auto") -> 202.87851 | E61: =_xll.PIArcVal(Sheet1!$A$2,Sheet1!C61,0,"","auto") -> 524.84717 | F61: =_xll.PIArcVal(Sheet1!$A$3,Sheet1!C61,0,"","auto") -> 401849.72 | G61: =_xll.PIArcVal(Sheet1!$A$4,Sheet1!C61,0,"","auto") -> 134733.75 | H61: =_xll.PIArcVal(Sheet1!$A$5,Sheet1!C61,0,"","auto") -> 44.480118 | I61: =_xll.PIArcVal(Sheet1!$A$6,Sheet1!C61,0,"","auto") -> 52.259499 | J61: =_xll.PIArcVal(Sheet1!$A$7,Sheet1!C61,0,"","auto") -> 42158.809 | K61: =_xll.PIArcVal(Sheet1!$A$8,Sheet1!C61,0,"","auto") -> 128138.71 | L61: =_xll.PIArcVal(Sheet1!$A$9,Sheet1!C61,0,"","auto") -> 1445.0388 | M61: =_xll.PIArcVal(Sheet1!$A$10,Sheet1!C61,0,"","auto") -> 1618.8097 | N61: =(J61+F61-F60)/(D61*H61/100)/1000 -> 0.45734572 | O61: =(K61+G61-G60)/(E61*I61/100)/1000 -> 0.45734362 | P61: =((J61+K61)+F61+G61-F60-G60)/(D61*H61/100+E61*I61/100)/1000 -> 0.45734414 | Q61: =P61*H61*10 -> 203.42721 | R61: =P61*I61*10 -> 239.00576 | S61: =((J61+K61)+F61+G61-F60-G60)/(D61+E61) -> 229.08702 | T61: =IF(AL61<3000,0,AL61) -> 65124.891 | U61: =IF(AM61<3000,0,AM61) -> 105240.56 | V61: =IF(AN61<3000,0,AN61) -> 0 | W61: ENA | X61: =J61+K61 -> 170297.52 | Y61: 0.617 | Z61: 0.624 | AA61: 0.62 | AB61: 264.32 | AC61: 323.34 | AD61: 44.27 | AE61: 52.51 | AF61: 1072 | AG61: 830 | AH61: 252143 | AI61: 0 | AJ61: 0 | AK61: 100000 | AL61: =_xll.PIArcVal(Sheet1!$A$11,Sheet1!C61,0,"","auto") -> 65124.891 | AM61: =_xll.PIArcVal(Sheet1!$A$12,Sheet1!C61,0,"","auto") -> 105240.56 | AN61: =_xll.PIArcVal(Sheet1!$A$13,Sheet1!C61,0,"","auto") -> -35.998703
B62: 46082 | C62: 46083 | D62: =_xll.PIArcVal(Sheet1!$A$1,Sheet1!C62,0,"","auto") -> 143.21257 | E62: =_xll.PIArcVal(Sheet1!$A$2,Sheet1!C62,0,"","auto") -> 405.64374 | F62: =_xll.PIArcVal(Sheet1!$A$3,Sheet1!C62,0,"","auto") -> 415831.12 | G62: =_xll.PIArcVal(Sheet1!$A$4,Sheet1!C62,0,"","auto") -> 180450.52 | H62: =_xll.PIArcVal(Sheet1!$A$5,Sheet1!C62,0,"","auto") -> 44.650215 | I62: =_xll.PIArcVal(Sheet1!$A$6,Sheet1!C62,0,"","auto") -> 51.540211 | J62: =_xll.PIArcVal(Sheet1!$A$7,Sheet1!C62,0,"","auto") -> 28945.197 | K62: =_xll.PIArcVal(Sheet1!$A$8,Sheet1!C62,0,"","auto") -> 94633.57 | L62: =_xll.PIArcVal(Sheet1!$A$9,Sheet1!C62,0,"","auto") -> 1069.0787 | M62: =_xll.PIArcVal(Sheet1!$A$10,Sheet1!C62,0,"","auto") -> 1115.1427 | N62: =(J62+F62-F61)/(D62*H62/100)/1000 -> 0.67130801 | O62: =(K62+G62-G61)/(E62*I62/100)/1000 -> 0.67130903 | P62: =((J62+K62)+F62+G62-F61-G61)/(D62*H62/100+E62*I62/100)/1000 -> 0.67130879 | Q62: =P62*H62*10 -> 299.74082 | R62: =P62*I62*10 -> 345.99397 | S62: =((J62+K62)+F62+G62-F61-G61)/(D62+E62) -> 333.92518 | T62: =IF(AL62<3000,0,AL62) -> 55842.078 | U62: =IF(AM62<3000,0,AM62) -> 67640.266 | V62: =IF(AN62<3000,0,AN62) -> 0 | W62: ENA | X62: =J62+K62 -> 123578.77 | Y62: 0.617 | Z62: 0.624 | AA62: 0.62 | AB62: 264.32 | AC62: 323.34 | AD62: 44.27 | AE62: 52.51 | AF62: 1072 | AG62: 830 | AH62: 252143 | AI62: 0 | AJ62: 0 | AK62: 210000 | AL62: =_xll.PIArcVal(Sheet1!$A$11,Sheet1!C62,0,"","auto") -> 55842.078 | AM62: =_xll.PIArcVal(Sheet1!$A$12,Sheet1!C62,0,"","auto") -> 67640.266 | AN62: =_xll.PIArcVal(Sheet1!$A$13,Sheet1!C62,0,"","auto") -> 76.001999
B63: 46083 | C63: 46084 | D63: =_xll.PIArcVal(Sheet1!$A$1,Sheet1!C63,0,"","auto") -> 190.1093 | E63: =_xll.PIArcVal(Sheet1!$A$2,Sheet1!C63,0,"","auto") -> 396.69876 | F63: =_xll.PIArcVal(Sheet1!$A$3,Sheet1!C63,0,"","auto") -> 427506.09 | G63: =_xll.PIArcVal(Sheet1!$A$4,Sheet1!C63,0,"","auto") -> 208538.14 | H63: =_xll.PIArcVal(Sheet1!$A$5,Sheet1!C63,0,"","auto") -> 44.959904 | I63: =_xll.PIArcVal(Sheet1!$A$6,Sheet1!C63,0,"","auto") -> 51.839825 | J63: =_xll.PIArcVal(Sheet1!$A$7,Sheet1!C63,0,"","auto") -> 45063.121 | K63: =_xll.PIArcVal(Sheet1!$A$8,Sheet1!C63,0,"","auto") -> 108421.88 | L63: =_xll.PIArcVal(Sheet1!$A$9,Sheet1!C63,0,"","auto") -> 1038.6761 | M63: =_xll.PIArcVal(Sheet1!$A$10,Sheet1!C63,0,"","auto") -> 1809.3284 | N63: =(J63+F63-F62)/(D63*H63/100)/1000 -> 0.66381334 | O63: =(K63+G63-G62)/(E63*I63/100)/1000 -> 0.66380193 | P63: =((J63+K63)+F63+G63-F62-G62)/(D63*H63/100+E63*I63/100)/1000 -> 0.66380528 | Q63: =P63*H63*10 -> 298.44621 | R63: =P63*I63*10 -> 344.11549 | S63: =((J63+K63)+F63+G63-F62-G62)/(D63+E63) -> 329.31993 | T63: =IF(AL63<3000,0,AL63) -> 62621.492 | U63: =IF(AM63<3000,0,AM63) -> 90588.945 | V63: =IF(AN63<3000,0,AN63) -> 0 | W63: ENA | X63: =J63+K63 -> 153485 | Y63: 0.617 | Z63: 0.624 | AA63: 0.62 | AB63: 264.32 | AC63: 323.34 | AD63: 44.27 | AE63: 52.51 | AF63: 1072 | AG63: 830 | AH63: 252143 | AI63: 0 | AJ63: 0 | AK63: 210000 | AL63: =_xll.PIArcVal(Sheet1!$A$11,Sheet1!C63,0,"","auto") -> 62621.492 | AM63: =_xll.PIArcVal(Sheet1!$A$12,Sheet1!C63,0,"","auto") -> 90588.945 | AN63: =_xll.PIArcVal(Sheet1!$A$13,Sheet1!C63,0,"","auto") -> 248.99681
B64: 46084 | C64: 46085 | D64: =_xll.PIArcVal(Sheet1!$A$1,Sheet1!C64,0,"","auto") -> 203.48477 | E64: =_xll.PIArcVal(Sheet1!$A$2,Sheet1!C64,0,"","auto") -> 466.80554 | F64: =_xll.PIArcVal(Sheet1!$A$3,Sheet1!C64,0,"","auto") -> 431948.91 | G64: =_xll.PIArcVal(Sheet1!$A$4,Sheet1!C64,0,"","auto") -> 220270.02 | H64: =_xll.PIArcVal(Sheet1!$A$5,Sheet1!C64,0,"","auto") -> 44.819778 | I64: =_xll.PIArcVal(Sheet1!$A$6,Sheet1!C64,0,"","auto") -> 51.589737 | J64: =_xll.PIArcVal(Sheet1!$A$7,Sheet1!C64,0,"","auto") -> 52429.516 | K64: =_xll.PIArcVal(Sheet1!$A$8,Sheet1!C64,0,"","auto") -> 138443.36 | L64: =_xll.PIArcVal(Sheet1!$A$9,Sheet1!C64,0,"","auto") -> 1148.2994 | M64: =_xll.PIArcVal(Sheet1!$A$10,Sheet1!C64,0,"","auto") -> 1390.2655 | N64: =(J64+F64-F63)/(D64*H64/100)/1000 -> 0.62359035 | O64: =(K64+G64-G63)/(E64*I64/100)/1000 -> 0.6235898 | P64: =((J64+K64)+F64+G64-F63-G63)/(D64*H64/100+E64*I64/100)/1000 -> 0.62358995 | Q64: =P64*H64*10 -> 279.49163 | R64: =P64*I64*10 -> 321.70842 | S64: =((J64+K64)+F64+G64-F63-G63)/(D64+E64) -> 308.89237 | T64: =IF(AL64<3000,0,AL64) -> 18867 | U64: =IF(AM64<3000,0,AM64) -> 172056 | V64: =IF(AN64<3000,0,AN64) -> 0 | W64: ENA | X64: =J64+K64 -> 190872.88 | Y64: 0.617 | Z64: 0.624 | AA64: 0.62 | AB64: 264.32 | AC64: 323.34 | AD64: 44.27 | AE64: 52.51 | AF64: 1072 | AG64: 830 | AH64: 252143 | AI64: 0 | AJ64: 0 | AK64: 210000 | AL64: =_xll.PIArcVal(Sheet1!$A$11,Sheet1!C64,0,"","auto") -> 18867 | AM64: =_xll.PIArcVal(Sheet1!$A$12,Sheet1!C64,0,"","auto") -> 172056 | AN64: =_xll.PIArcVal(Sheet1!$A$13,Sheet1!C64,0,"","auto") -> -27
B65: 46085 | C65: 46086 | D65: =_xll.PIArcVal(Sheet1!$A$1,Sheet1!C65,0,"","auto") -> 210.35001 | E65: =_xll.PIArcVal(Sheet1!$A$2,Sheet1!C65,0,"","auto") -> 374.06 | F65: =_xll.PIArcVal(Sheet1!$A$3,Sheet1!C65,0,"","auto") -> 437588 | G65: =_xll.PIArcVal(Sheet1!$A$4,Sheet1!C65,0,"","auto") -> 231812 | H65: =_xll.PIArcVal(Sheet1!$A$5,Sheet1!C65,0,"","auto") -> 44.5 | I65: =_xll.PIArcVal(Sheet1!$A$6,Sheet1!C65,0,"","auto") -> 51.209999 | J65: =_xll.PIArcVal(Sheet1!$A$7,Sheet1!C65,0,"","auto") -> 51730 | K65: =_xll.PIArcVal(Sheet1!$A$8,Sheet1!C65,0,"","auto") -> 105861 | L65: =_xll.PIArcVal(Sheet1!$A$9,Sheet1!C65,0,"","auto") -> 1147.4 | M65: =_xll.PIArcVal(Sheet1!$A$10,Sheet1!C65,0,"","auto") -> 2204.1599 | N65: =(J65+F65-F64)/(D65*H65/100)/1000 -> 0.61288 | O65: =(K65+G65-G64)/(E65*I65/100)/1000 -> 0.6128908 | P65: =((J65+K65)+F65+G65-F64-G64)/(D65*H65/100+E65*I65/100)/1000 -> 0.61288725 | Q65: =P65*H65*10 -> 272.73483 | R65: =P65*I65*10 -> 313.85956 | S65: =((J65+K65)+F65+G65-F64-G64)/(D65+E65) -> 299.0573 | T65: =IF(AL65<3000,0,AL65) -> 18867 | U65: =IF(AM65<3000,0,AM65) -> 172056 | V65: =IF(AN65<3000,0,AN65) -> 0 | W65: ENA | X65: =J65+K65 -> 157591 | Y65: 0.617 | Z65: 0.624 | AA65: 0.62 | AB65: 264.32 | AC65: 323.34 | AD65: 44.27 | AE65: 52.51 | AF65: 1072 | AG65: 830 | AH65: 252143 | AI65: 0 | AJ65: 0 | AK65: 210000 | AL65: =_xll.PIArcVal(Sheet1!$A$11,Sheet1!C65,0,"","auto") -> 18867 | AM65: =_xll.PIArcVal(Sheet1!$A$12,Sheet1!C65,0,"","auto") -> 172056 | AN65: =_xll.PIArcVal(Sheet1!$A$13,Sheet1!C65,0,"","auto") -> -27
B66: 46086 | C66: 46087 | D66: =_xll.PIArcVal(Sheet1!$A$1,Sheet1!C66,0,"","auto") -> 200.49001 | E66: =_xll.PIArcVal(Sheet1!$A$2,Sheet1!C66,0,"","auto") -> 391.59 | F66: =_xll.PIArcVal(Sheet1!$A$3,Sheet1!C66,0,"","auto") -> 433056 | G66: =_xll.PIArcVal(Sheet1!$A$4,Sheet1!C66,0,"","auto") -> 221623 | H66: =_xll.PIArcVal(Sheet1!$A$5,Sheet1!C66,0,"","auto") -> 44.509998 | I66: =_xll.PIArcVal(Sheet1!$A$6,Sheet1!C66,0,"","auto") -> 51.23 | J66: =_xll.PIArcVal(Sheet1!$A$7,Sheet1!C66,0,"","auto") -> 61016 | K66: =_xll.PIArcVal(Sheet1!$A$8,Sheet1!C66,0,"","auto") -> 137167 | L66: =_xll.PIArcVal(Sheet1!$A$9,Sheet1!C66,0,"","auto") -> 1283.5 | M66: =_xll.PIArcVal(Sheet1!$A$10,Sheet1!C66,0,"","auto") -> 2230.3899 | N66: =(J66+F66-F65)/(D66*H66/100)/1000 -> 0.63295836 | O66: =(K66+G66-G65)/(E66*I66/100)/1000 -> 0.63295457 | P66: =((J66+K66)+F66+G66-F65-G65)/(D66*H66/100+E66*I66/100)/1000 -> 0.63295574 | Q66: =P66*H66*10 -> 281.72859 | R66: =P66*I66*10 -> 324.26322 | S66: =((J66+K66)+F66+G66-F65-G65)/(D66+E66) -> 309.86015 | T66: =IF(AL66<3000,0,AL66) -> 71739 | U66: =IF(AM66<3000,0,AM66) -> 85811 | V66: =IF(AN66<3000,0,AN66) -> 0 | W66: ENA | X66: =J66+K66 -> 198183 | Y66: 0.617 | Z66: 0.624 | AA66: 0.62 | AB66: 264.32 | AC66: 323.34 | AD66: 44.27 | AE66: 52.51 | AF66: 1072 | AG66: 830 | AH66: 252143 | AI66: 0 | AJ66: 0 | AK66: 210000 | AL66: =_xll.PIArcVal(Sheet1!$A$11,Sheet1!C66,0,"","auto") -> 71739 | AM66: =_xll.PIArcVal(Sheet1!$A$12,Sheet1!C66,0,"","auto") -> 85811 | AN66: =_xll.PIArcVal(Sheet1!$A$13,Sheet1!C66,0,"","auto") -> 41
B67: 46087 | C67: 46088 | D67: =_xll.PIArcVal(Sheet1!$A$1,Sheet1!C67,0,"","auto") -> 201.21138 | E67: =_xll.PIArcVal(Sheet1!$A$2,Sheet1!C67,0,"","auto") -> 562.21747 | F67: =_xll.PIArcVal(Sheet1!$A$3,Sheet1!C67,0,"","auto") -> 437306.59 | G67: =_xll.PIArcVal(Sheet1!$A$4,Sheet1!C67,0,"","auto") -> 235282.81 | H67: =_xll.PIArcVal(Sheet1!$A$5,Sheet1!C67,0,"","auto") -> 44.749916 | I67: =_xll.PIArcVal(Sheet1!$A$6,Sheet1!C67,0,"","auto") -> 51.459812 | J67: =_xll.PIArcVal(Sheet1!$A$7,Sheet1!C67,0,"","auto") -> 50977.297 | K67: =_xll.PIArcVal(Sheet1!$A$8,Sheet1!C67,0,"","auto") -> 163796.03 | L67: =_xll.PIArcVal(Sheet1!$A$9,Sheet1!C67,0,"","auto") -> 1513.0636 | M67: =_xll.PIArcVal(Sheet1!$A$10,Sheet1!C67,0,"","auto") -> 2154.2141 | N67: =(J67+F67-F66)/(D67*H67/100)/1000 -> 0.61335752 | O67: =(K67+G67-G66)/(E67*I67/100)/1000 -> 0.61336328 | P67: =((J67+K67)+F67+G67-F66-G66)/(D67*H67/100+E67*I67/100)/1000 -> 0.61336191 | Q67: =P67*H67*10 -> 274.47894 | R67: =P67*I67*10 -> 315.63489 | S67: =((J67+K67)+F67+G67-F66-G66)/(D67+E67) -> 304.78772 | T67: =IF(AL67<3000,0,AL67) -> 0 | U67: =IF(AM67<3000,0,AM67) -> 214874.09 | V67: =IF(AN67<3000,0,AN67) -> 0 | W67: ENA | X67: =J67+K67 -> 214773.33 | Y67: 0.617 | Z67: 0.624 | AA67: 0.62 | AB67: 264.32 | AC67: 323.34 | AD67: 44.27 | AE67: 52.51 | AF67: 1072 | AG67: 830 | AH67: 252143 | AI67: 0 | AJ67: 0 | AK67: 210000 | AL67: =_xll.PIArcVal(Sheet1!$A$11,Sheet1!C67,0,"","auto") -> -106.99947 | AM67: =_xll.PIArcVal(Sheet1!$A$12,Sheet1!C67,0,"","auto") -> 214874.09 | AN67: =_xll.PIArcVal(Sheet1!$A$13,Sheet1!C67,0,"","auto") -> 0.0060416665
B68: 46088 | C68: 46089 | D68: =_xll.PIArcVal(Sheet1!$A$1,Sheet1!C68,0,"","auto") -> 160.03989 | E68: =_xll.PIArcVal(Sheet1!$A$2,Sheet1!C68,0,"","auto") -> 616.08832 | F68: =_xll.PIArcVal(Sheet1!$A$3,Sheet1!C68,0,"","auto") -> 442472.16 | G68: =_xll.PIArcVal(Sheet1!$A$4,Sheet1!C68,0,"","auto") -> 258081.98 | H68: =_xll.PIArcVal(Sheet1!$A$5,Sheet1!C68,0,"","auto") -> 44.630238 | I68: =_xll.PIArcVal(Sheet1!$A$6,Sheet1!C68,0,"","auto") -> 51.190254 | J68: =_xll.PIArcVal(Sheet1!$A$7,Sheet1!C68,0,"","auto") -> 41330.398 | K68: =_xll.PIArcVal(Sheet1!$A$8,Sheet1!C68,0,"","auto") -> 182499.48 | L68: =_xll.PIArcVal(Sheet1!$A$9,Sheet1!C68,0,"","auto") -> 1172.7761 | M68: =_xll.PIArcVal(Sheet1!$A$10,Sheet1!C68,0,"","auto") -> 2620.5217 | N68: =(J68+F68-F67)/(D68*H68/100)/1000 -> 0.65096523 | O68: =(K68+G68-G67)/(E68*I68/100)/1000 -> 0.65096231 | P68: =((J68+K68)+F68+G68-F67-G67)/(D68*H68/100+E68*I68/100)/1000 -> 0.65096285 | Q68: =P68*H68*10 -> 290.52627 | R68: =P68*I68*10 -> 333.22954 | S68: =((J68+K68)+F68+G68-F67-G67)/(D68+E68) -> 324.424 | T68: =IF(AL68<3000,0,AL68) -> 0 | U68: =IF(AM68<3000,0,AM68) -> 223406.3 | V68: =IF(AN68<3000,0,AN68) -> 0 | W68: ENA | X68: =J68+K68 -> 223829.88 | Y68: 0.617 | Z68: 0.624 | AA68: 0.62 | AB68: 264.32 | AC68: 323.34 | AD68: 44.27 | AE68: 52.51 | AF68: 1072 | AG68: 830 | AH68: 252143 | AI68: 0 | AJ68: 0 | AK68: 210000 | AL68: =_xll.PIArcVal(Sheet1!$A$11,Sheet1!C68,0,"","auto") -> -59.948277 | AM68: =_xll.PIArcVal(Sheet1!$A$12,Sheet1!C68,0,"","auto") -> 223406.3 | AN68: =_xll.PIArcVal(Sheet1!$A$13,Sheet1!C68,0,"","auto") -> 521.99316
B69: 46089 | C69: 46090 | D69: =_xll.PIArcVal(Sheet1!$A$1,Sheet1!C69,0,"","auto") -> 203.01662 | E69: =_xll.PIArcVal(Sheet1!$A$2,Sheet1!C69,0,"","auto") -> 555.98389 | F69: =_xll.PIArcVal(Sheet1!$A$3,Sheet1!C69,0,"","auto") -> 458506.31 | G69: =_xll.PIArcVal(Sheet1!$A$4,Sheet1!C69,0,"","auto") -> 308427.06 | H69: =_xll.PIArcVal(Sheet1!$A$5,Sheet1!C69,0,"","auto") -> 44.969475 | I69: =_xll.PIArcVal(Sheet1!$A$6,Sheet1!C69,0,"","auto") -> 51.560154 | J69: =_xll.PIArcVal(Sheet1!$A$7,Sheet1!C69,0,"","auto") -> 40465.602 | K69: =_xll.PIArcVal(Sheet1!$A$8,Sheet1!C69,0,"","auto") -> 127062.2 | L69: =_xll.PIArcVal(Sheet1!$A$9,Sheet1!C69,0,"","auto") -> 1138.4407 | M69: =_xll.PIArcVal(Sheet1!$A$10,Sheet1!C69,0,"","auto") -> 2076.8643 | N69: =(J69+F69-F68)/(D69*H69/100)/1000 -> 0.6188668 | O69: =(K69+G69-G68)/(E69*I69/100)/1000 -> 0.6188637 | P69: =((J69+K69)+F69+G69-F68-G68)/(D69*H69/100+E69*I69/100)/1000 -> 0.61886445 | Q69: =P69*H69*10 -> 278.30009 | R69: =P69*I69*10 -> 319.08746 | S69: =((J69+K69)+F69+G69-F68-G68)/(D69+E69) -> 308.1777 | T69: =IF(AL69<3000,0,AL69) -> 90808 | U69: =IF(AM69<3000,0,AM69) -> 76791 | V69: =IF(AN69<3000,0,AN69) -> 0 | W69: ENA | X69: =J69+K69 -> 167527.8 | Y69: 0.617 | Z69: 0.624 | AA69: 0.62 | AB69: 264.32 | AC69: 323.34 | AD69: 44.27 | AE69: 52.51 | AF69: 1072 | AG69: 830 | AH69: 252143 | AI69: 0 | AJ69: 0 | AK69: 210000 | AL69: =_xll.PIArcVal(Sheet1!$A$11,Sheet1!C69,0,"","auto") -> 90808 | AM69: =_xll.PIArcVal(Sheet1!$A$12,Sheet1!C69,0,"","auto") -> 76791 | AN69: =_xll.PIArcVal(Sheet1!$A$13,Sheet1!C69,0,"","auto") -> -67
...
